<sdf version='1.7'>
  <model name='spot_micro'>
    <link name='base_link'>
      <inertial>
        <pose>0 0 0.00473 0 -0 0</pose>
        <mass>3.7</mass>
        <inertia>
          <ixx>400.001</ixx>
          <ixy>0</ixy>
          <ixz>0</ixz>
          <iyy>400.001</iyy>
          <iyz>0</iyz>
          <izz>400</izz>
        </inertia>
      </inertial>
      <collision name='base_link_collision'>
        <pose>0 0 0 0 -0 0</pose>
        <geometry>
          <box>
            <size>0.14 0.11 0.07</size>
          </box>
        </geometry>
      </collision>
      <collision name='base_link_fixed_joint_lump__front_link_collision_1'>
        <pose>-0.145 0 0 0 -0 0</pose>
        <geometry>
          <box>
            <size>0.058 0.11 0.07</size>
          </box>
        </geometry>
      </collision>
      <collision name='base_link_fixed_joint_lump__lidar_link_collision_2'>
        <pose>0 0 0.035 0 -0 0</pose>
        <geometry>
          <box>
            <size>0.0985 0.0577 0.07</size>
          </box>
        </geometry>
      </collision>
      <collision name='base_link_fixed_joint_lump__rear_link_collision_3'>
        <pose>0.135 0 0 0 -0 0</pose>
        <geometry>
          <box>
            <size>0.04 0.11 0.07</size>
          </box>
        </geometry>
      </collision>
      <visual name='base_link_visual'>
        <pose>-0.042 -0.055 -0.01 0 -0 0</pose>
        <geometry>
          <mesh>
            <scale>0.001 0.001 0.001</scale>
            <uri>model://spot_micro/meshes/mainbody.stl</uri>
          </mesh>
        </geometry>
      </visual>
      <visual name='base_link_fixed_joint_lump__front_link_visual_1'>
        <pose>0.04 0.055 -0.01 0 -0 3.14159</pose>
        <geometry>
          <mesh>
            <scale>0.001 0.001 0.001</scale>
            <uri>model://spot_micro/meshes/frontpart.stl</uri>
          </mesh>
        </geometry>
      </visual>
      <visual name='base_link_fixed_joint_lump__lidar_link_visual_2'>
        <pose>-0.03425 0.03585 0.035 1.57075 -0 0</pose>
        <geometry>
          <mesh>
            <scale>0.001 0.001 0.001</scale>
            <uri>model://spot_micro/meshes/rplidar_main.STL</uri>
          </mesh>
        </geometry>
      </visual>
      <visual name='base_link_fixed_joint_lump__rear_link_visual_3'>
        <pose>0.04 0.055 -0.01 0 -0 3.14159</pose>
        <geometry>
          <mesh>
            <scale>0.001 0.001 0.001</scale>
            <uri>model://spot_micro/meshes/backpart.stl</uri>
          </mesh>
        </geometry>
      </visual>
    </link>
    <joint name='front_left_shoulder' type='revolute'>
      <pose relative_to='base_link'>0.093 0.039 0 0 -0 0</pose>
      <parent>base_link</parent>
      <child>front_left_shoulder_link</child>
      <axis>
        <xyz>1 0 0</xyz>
        <limit>
          <lower>-0.548</lower>
          <upper>0.548</upper>
          <effort>1000</effort>
          <velocity>0.7</velocity>
        </limit>
        <dynamics>
          <damping>0</damping>
          <friction>0.5</friction>
          <spring_reference>0</spring_reference>
          <spring_stiffness>0</spring_stiffness>
        </dynamics>
      </axis>
    </joint>
    <link name='front_left_shoulder_link'>
      <pose relative_to='front_left_shoulder'>0 0 0 0 -0 0</pose>
      <inertial>
        <pose>0 0 0 0 -0 0</pose>
        <mass>0.1</mass>
        <inertia>
          <ixx>100</ixx>
          <ixy>0</ixy>
          <ixz>0</ixz>
          <iyy>100</iyy>
          <iyz>0</iyz>
          <izz>100</izz>
        </inertia>
      </inertial>
      <collision name='front_left_shoulder_link_collision'>
        <pose>0 0 0 0 -0 0</pose>
        <geometry>
          <box>
            <size>0.044 0.038 0.07</size>
          </box>
        </geometry>
      </collision>
      <visual name='front_left_shoulder_link_visual'>
        <pose>0.135 0.015 -0.01 0 -0 3.14159</pose>
        <geometry>
          <mesh>
            <scale>0.001 0.001 0.001</scale>
            <uri>model://spot_micro/meshes/lshoulder.stl</uri>
          </mesh>
        </geometry>
      </visual>
    </link>
    <joint name='front_left_leg' type='revolute'>
      <pose relative_to='front_left_shoulder_link'>0 0.055 0 0 -0 0</pose>
      <parent>front_left_shoulder_link</parent>
      <child>front_left_leg_link</child>
      <axis>
        <xyz>0 1 0</xyz>
        <limit>
          <lower>-2.666</lower>
          <upper>1.548</upper>
          <effort>1000</effort>
          <velocity>0.5</velocity>
        </limit>
        <dynamics>
          <damping>0</damping>
          <friction>0</friction>
          <spring_reference>0</spring_reference>
          <spring_stiffness>0</spring_stiffness>
        </dynamics>
      </axis>
    </joint>
    <link name='front_left_leg_link'>
      <pose relative_to='front_left_leg'>0 0 0 0 -0 0</pose>
      <inertial>
        <pose>0 0 0 0 -0 0</pose>
        <mass>0.15</mass>
        <inertia>
          <ixx>1000</ixx>
          <ixy>0</ixy>
          <ixz>0</ixz>
          <iyy>1000</iyy>
          <iyz>0</iyz>
          <izz>1000</izz>
        </inertia>
      </inertial>
      <collision name='front_left_leg_link_collision'>
        <pose>0 0 -0.05 0 -0 0</pose>
        <geometry>
          <box>
            <size>0.028 0.036 0.1075</size>
          </box>
        </geometry>
      </collision>
      <visual name='front_left_leg_link_visual'>
        <pose>0.13 -0.04 -0.025 0 -0.139 3.14159</pose>
        <geometry>
          <mesh>
            <scale>0.001 0.001 0.001</scale>
            <uri>model://spot_micro/meshes/larm.stl</uri>
          </mesh>
        </geometry>
      </visual>
      <visual name='front_left_leg_link_cover_visual_1'>
        <pose>0.13 -0.04 -0.025 0 -0.139 3.14159</pose>
        <geometry>
          <mesh>
            <scale>0.001 0.001 0.001</scale>
            <uri>model://spot_micro/meshes/larm_cover.stl</uri>
          </mesh>
        </geometry>
      </visual>
    </link>
    <joint name='front_left_foot' type='revolute'>
      <pose relative_to='front_left_leg_link'>0 0 -0.1075 0 -0 0</pose>
      <parent>front_left_leg_link</parent>
      <child>front_left_foot_link</child>
      <axis>
        <xyz>0 1 0</xyz>
        <limit>
          <lower>-2.6</lower>
          <upper>0.1</upper>
          <effort>1000</effort>
          <velocity>0.5</velocity>
        </limit>
        <dynamics>
          <damping>0</damping>
          <friction>0.5</friction>
          <spring_reference>0</spring_reference>
          <spring_stiffness>0</spring_stiffness>
        </dynamics>
      </axis>
    </joint>
    <link name='front_left_foot_link'>
      <pose relative_to='front_left_foot'>0 0 0 0 -0 0</pose>
      <inertial>
        <pose>0 0 -0.043333 0 -0 0</pose>
        <mass>0.15</mass>
        <inertia>
          <ixx>2000</ixx>
          <ixy>0</ixy>
          <ixz>0</ixz>
          <iyy>2000</iyy>
          <iyz>0</iyz>
          <izz>2000</izz>
        </inertia>
      </inertial>
      <collision name='front_left_foot_link_collision'>
        <pose>0 0 -0.05 0 -0 0</pose>
        <geometry>
          <box>
            <size>0.026 0.02 0.13</size>
          </box>
        </geometry>
      </collision>
      <collision name='front_left_foot_link_fixed_joint_lump__front_left_toe_link_collision_1'>
        <pose>0 0 -0.11 0 -0 0</pose>
        <geometry>
          <sphere>
            <radius>0.02</radius>
          </sphere>
        </geometry>
      </collision>
      <visual name='front_left_foot_link_visual'>
        <pose>0.12 -0.04 0.1 0 -0 3.14159</pose>
        <geometry>
          <mesh>
            <scale>0.001 0.001 0.001</scale>
            <uri>model://spot_micro/meshes/lfoot.stl</uri>
          </mesh>
        </geometry>
      </visual>
      <visual name='front_left_foot_link_fixed_joint_lump__front_left_toe_link_visual_1'>
        <pose>0 0.01 -0.115 0 -0.4001 3.14159</pose>
        <geometry>
          <mesh>
            <scale>0.001 0.001 0.001</scale>
            <uri>model://spot_micro/meshes/foot.stl</uri>
          </mesh>
        </geometry>
      </visual>
    </link>
    <joint name='front_right_shoulder' type='revolute'>
      <pose relative_to='base_link'>0.093 -0.039 0 0 -0 0</pose>
      <parent>base_link</parent>
      <child>front_right_shoulder_link</child>
      <axis>
        <xyz>1 0 0</xyz>
        <limit>
          <lower>-0.548</lower>
          <upper>0.548</upper>
          <effort>1000</effort>
          <velocity>0.7</velocity>
        </limit>
        <dynamics>
          <damping>0</damping>
          <friction>0.5</friction>
          <spring_reference>0</spring_reference>
          <spring_stiffness>0</spring_stiffness>
        </dynamics>
      </axis>
    </joint>
    <link name='front_right_shoulder_link'>
      <pose relative_to='front_right_shoulder'>0 0 0 0 -0 0</pose>
      <inertial>
        <pose>0 0 0 0 -0 0</pose>
        <mass>0.1</mass>
        <inertia>
          <ixx>100</ixx>
          <ixy>0</ixy>
          <ixz>0</ixz>
          <iyy>100</iyy>
          <iyz>0</iyz>
          <izz>100</izz>
        </inertia>
      </inertial>
      <collision name='front_right_shoulder_link_collision'>
        <pose>0 0 0 0 -0 0</pose>
        <geometry>
          <box>
            <size>0.044 0.038 0.07</size>
          </box>
        </geometry>
      </collision>
      <visual name='front_right_shoulder_link_visual'>
        <pose>0.135 0.095 -0.01 0 -0 3.14159</pose>
        <geometry>
          <mesh>
            <scale>0.001 0.001 0.001</scale>
            <uri>model://spot_micro/meshes/rshoulder.stl</uri>
          </mesh>
        </geometry>
      </visual>
    </link>
    <joint name='front_right_leg' type='revolute'>
      <pose relative_to='front_right_shoulder_link'>0 -0.055 0 0 -0 0</pose>
      <parent>front_right_shoulder_link</parent>
      <child>front_right_leg_link</child>
      <axis>
        <xyz>0 1 0</xyz>
        <limit>
          <lower>-2.666</lower>
          <upper>1.548</upper>
          <effort>1000</effort>
          <velocity>0.5</velocity>
        </limit>
        <dynamics>
          <damping>0</damping>
          <friction>0</friction>
          <spring_reference>0</spring_reference>
          <spring_stiffness>0</spring_stiffness>
        </dynamics>
      </axis>
    </joint>
    <link name='front_right_leg_link'>
      <pose relative_to='front_right_leg'>0 0 0 0 -0 0</pose>
      <inertial>
        <pose>0 0 0 0 -0 0</pose>
        <mass>0.15</mass>
        <inertia>
          <ixx>1000</ixx>
          <ixy>0</ixy>
          <ixz>0</ixz>
          <iyy>1000</iyy>
          <iyz>0</iyz>
          <izz>1000</izz>
        </inertia>
      </inertial>
      <collision name='front_right_leg_link_collision'>
        <pose>0 0 -0.05 0 -0 0</pose>
        <geometry>
          <box>
            <size>0.028 0.036 0.1075</size>
          </box>
        </geometry>
      </collision>
      <visual name='front_right_leg_link_visual'>
        <pose>0.13 0.15 -0.025 0 -0.139 3.14159</pose>
        <geometry>
          <mesh>
            <scale>0.001 0.001 0.001</scale>
            <uri>model://spot_micro/meshes/rarm.stl</uri>
          </mesh>
        </geometry>
      </visual>
      <visual name='front_right_leg_link_cover_visual_1'>
        <pose>0.13 0.15 -0.025 0 -0.139 3.14159</pose>
        <geometry>
          <mesh>
            <scale>0.001 0.001 0.001</scale>
            <uri>model://spot_micro/meshes/rarm_cover.stl</uri>
          </mesh>
        </geometry>
      </visual>
    </link>
    <joint name='front_right_foot' type='revolute'>
      <pose relative_to='front_right_leg_link'>0 0 -0.1075 0 -0 0</pose>
      <parent>front_right_leg_link</parent>
      <child>front_right_foot_link</child>
      <axis>
        <xyz>0 1 0</xyz>
        <limit>
          <lower>-2.6</lower>
          <upper>0.1</upper>
          <effort>1000</effort>
          <velocity>0.5</velocity>
        </limit>
        <dynamics>
          <damping>0</damping>
          <friction>0.5</friction>
          <spring_reference>0</spring_reference>
          <spring_stiffness>0</spring_stiffness>
        </dynamics>
      </axis>
    </joint>
    <link name='front_right_foot_link'>
      <pose relative_to='front_right_foot'>0 0 0 0 -0 0</pose>
      <inertial>
        <pose>0 0 -0.043333 0 -0 0</pose>
        <mass>0.15</mass>
        <inertia>
          <ixx>2000</ixx>
          <ixy>0</ixy>
          <ixz>0</ixz>
          <iyy>2000</iyy>
          <iyz>0</iyz>
          <izz>2000</izz>
        </inertia>
      </inertial>
      <collision name='front_right_foot_link_collision'>
        <pose>0 0 -0.05 0 -0 0</pose>
        <geometry>
          <box>
            <size>0.026 0.02 0.13</size>
          </box>
        </geometry>
      </collision>
      <collision name='front_right_foot_link_fixed_joint_lump__front_right_toe_link_collision_1'>
        <pose>0 0 -0.11 0 -0 0</pose>
        <geometry>
          <sphere>
            <radius>0.02</radius>
          </sphere>
        </geometry>
      </collision>
      <visual name='front_right_foot_link_visual'>
        <pose>0.12 0.15 0.1 0 -0 3.14159</pose>
        <geometry>
          <mesh>
            <scale>0.001 0.001 0.001</scale>
            <uri>model://spot_micro/meshes/rfoot.stl</uri>
          </mesh>
        </geometry>
      </visual>
      <visual name='front_right_foot_link_fixed_joint_lump__front_right_toe_link_visual_1'>
        <pose>0 0.01 -0.115 0 -0.4001 3.14159</pose>
        <geometry>
          <mesh>
            <scale>0.001 0.001 0.001</scale>
            <uri>model://spot_micro/meshes/foot.stl</uri>
          </mesh>
        </geometry>
      </visual>
    </link>
    <joint name='rear_left_shoulder' type='revolute'>
      <pose relative_to='base_link'>-0.093 0.039 0 0 -0 0</pose>
      <parent>base_link</parent>
      <child>rear_left_shoulder_link</child>
      <axis>
        <xyz>1 0 0</xyz>
        <limit>
          <lower>-0.548</lower>
          <upper>0.548</upper>
          <effort>1000</effort>
          <velocity>0.7</velocity>
        </limit>
        <dynamics>
          <damping>0</damping>
          <friction>0.5</friction>
          <spring_reference>0</spring_reference>
          <spring_stiffness>0</spring_stiffness>
        </dynamics>
      </axis>
    </joint>
    <link name='rear_left_shoulder_link'>
      <pose relative_to='rear_left_shoulder'>0 0 0 0 -0 0</pose>
      <inertial>
        <pose>0 0 0 0 -0 0</pose>
        <mass>0.1</mass>
        <inertia>
          <ixx>100</ixx>
          <ixy>0</ixy>
          <ixz>0</ixz>
          <iyy>100</iyy>
          <iyz>0</iyz>
          <izz>100</izz>
        </inertia>
      </inertial>
      <collision name='rear_left_shoulder_link_collision'>
        <pose>0 0 0 0 -0 0</pose>
        <geometry>
          <box>
            <size>0.044 0.038 0.07</size>
          </box>
        </geometry>
      </collision>
      <visual name='rear_left_shoulder_link_visual'>
        <pose>0.135 0.015 -0.01 0 -0 3.14159</pose>
        <geometry>
          <mesh>
            <scale>0.001 0.001 0.001</scale>
            <uri>model://spot_micro/meshes/lshoulder.stl</uri>
          </mesh>
        </geometry>
      </visual>
    </link>
    <joint name='rear_left_leg' type='revolute'>
      <pose relative_to='rear_left_shoulder_link'>0 0.055 0 0 -0 0</pose>
      <parent>rear_left_shoulder_link</parent>
      <child>rear_left_leg_link</child>
      <axis>
        <xyz>0 1 0</xyz>
        <limit>
          <lower>-2.666</lower>
          <upper>1.548</upper>
          <effort>1000</effort>
          <velocity>0.5</velocity>
        </limit>
        <dynamics>
          <damping>0</damping>
          <friction>0</friction>
          <spring_reference>0</spring_reference>
          <spring_stiffness>0</spring_stiffness>
        </dynamics>
      </axis>
    </joint>
    <link name='rear_left_leg_link'>
      <pose relative_to='rear_left_leg'>0 0 0 0 -0 0</pose>
      <inertial>
        <pose>0 0 0 0 -0 0</pose>
        <mass>0.15</mass>
        <inertia>
          <ixx>1000</ixx>
          <ixy>0</ixy>
          <ixz>0</ixz>
          <iyy>1000</iyy>
          <iyz>0</iyz>
          <izz>1000</izz>
        </inertia>
      </inertial>
      <collision name='rear_left_leg_link_collision'>
        <pose>0 0 -0.05 0 -0 0</pose>
        <geometry>
          <box>
            <size>0.028 0.036 0.1075</size>
          </box>
        </geometry>
      </collision>
      <visual name='rear_left_leg_link_visual'>
        <pose>0.13 -0.04 -0.025 0 -0.139 3.14159</pose>
        <geometry>
          <mesh>
            <scale>0.001 0.001 0.001</scale>
            <uri>model://spot_micro/meshes/larm.stl</uri>
          </mesh>
        </geometry>
      </visual>
      <visual name='rear_left_leg_link_cover_visual_1'>
        <pose>0.13 -0.04 -0.025 0 -0.139 3.14159</pose>
        <geometry>
          <mesh>
            <scale>0.001 0.001 0.001</scale>
            <uri>model://spot_micro/meshes/larm_cover.stl</uri>
          </mesh>
        </geometry>
      </visual>
    </link>
    <joint name='rear_left_foot' type='revolute'>
      <pose relative_to='rear_left_leg_link'>0 0 -0.1075 0 -0 0</pose>
      <parent>rear_left_leg_link</parent>
      <child>rear_left_foot_link</child>
      <axis>
        <xyz>0 1 0</xyz>
        <limit>
          <lower>-2.6</lower>
          <upper>0.1</upper>
          <effort>1000</effort>
          <velocity>0.5</velocity>
        </limit>
        <dynamics>
          <damping>0</damping>
          <friction>0.5</friction>
          <spring_reference>0</spring_reference>
          <spring_stiffness>0</spring_stiffness>
        </dynamics>
      </axis>
    </joint>
    <link name='rear_left_foot_link'>
      <pose relative_to='rear_left_foot'>0 0 0 0 -0 0</pose>
      <inertial>
        <pose>0 0 -0.043333 0 -0 0</pose>
        <mass>0.15</mass>
        <inertia>
          <ixx>2000</ixx>
          <ixy>0</ixy>
          <ixz>0</ixz>
          <iyy>2000</iyy>
          <iyz>0</iyz>
          <izz>2000</izz>
        </inertia>
      </inertial>
      <collision name='rear_left_foot_link_collision'>
        <pose>0 0 -0.05 0 -0 0</pose>
        <geometry>
          <box>
            <size>0.026 0.02 0.13</size>
          </box>
        </geometry>
      </collision>
      <collision name='rear_left_foot_link_fixed_joint_lump__rear_left_toe_link_collision_1'>
        <pose>0 0 -0.11 0 -0 0</pose>
        <geometry>
          <sphere>
            <radius>0.02</radius>
          </sphere>
        </geometry>
      </collision>
      <visual name='rear_left_foot_link_visual'>
        <pose>0.12 -0.04 0.1 0 -0 3.14159</pose>
        <geometry>
          <mesh>
            <scale>0.001 0.001 0.001</scale>
            <uri>model://spot_micro/meshes/lfoot.stl</uri>
          </mesh>
        </geometry>
      </visual>
      <visual name='rear_left_foot_link_fixed_joint_lump__rear_left_toe_link_visual_1'>
        <pose>0 0.01 -0.115 0 -0.4001 3.14159</pose>
        <geometry>
          <mesh>
            <scale>0.001 0.001 0.001</scale>
            <uri>model://spot_micro/meshes/foot.stl</uri>
          </mesh>
        </geometry>
      </visual>
    </link>
    <joint name='rear_right_shoulder' type='revolute'>
      <pose relative_to='base_link'>-0.093 -0.039 0 0 -0 0</pose>
      <parent>base_link</parent>
      <child>rear_right_shoulder_link</child>
      <axis>
        <xyz>1 0 0</xyz>
        <limit>
          <lower>-0.548</lower>
          <upper>0.548</upper>
          <effort>1000</effort>
          <velocity>0.7</velocity>
        </limit>
        <dynamics>
          <damping>0</damping>
          <friction>0.5</friction>
          <spring_reference>0</spring_reference>
          <spring_stiffness>0</spring_stiffness>
        </dynamics>
      </axis>
    </joint>
    <link name='rear_right_shoulder_link'>
      <pose relative_to='rear_right_shoulder'>0 0 0 0 -0 0</pose>
      <inertial>
        <pose>0 0 0 0 -0 0</pose>
        <mass>0.1</mass>
        <inertia>
          <ixx>100</ixx>
          <ixy>0</ixy>
          <ixz>0</ixz>
          <iyy>100</iyy>
          <iyz>0</iyz>
          <izz>100</izz>
        </inertia>
      </inertial>
      <collision name='rear_right_shoulder_link_collision'>
        <pose>0 0 0 0 -0 0</pose>
        <geometry>
          <box>
            <size>0.044 0.038 0.07</size>
          </box>
        </geometry>
      </collision>
      <visual name='rear_right_shoulder_link_visual'>
        <pose>0.135 0.095 -0.01 0 -0 3.14159</pose>
        <geometry>
          <mesh>
            <scale>0.001 0.001 0.001</scale>
            <uri>model://spot_micro/meshes/rshoulder.stl</uri>
          </mesh>
        </geometry>
      </visual>
    </link>
    <joint name='rear_right_leg' type='revolute'>
      <pose relative_to='rear_right_shoulder_link'>0 -0.055 0 0 -0 0</pose>
      <parent>rear_right_shoulder_link</parent>
      <child>rear_right_leg_link</child>
      <axis>
        <xyz>0 1 0</xyz>
        <limit>
          <lower>-2.666</lower>
          <upper>1.548</upper>
          <effort>1000</effort>
          <velocity>0.5</velocity>
        </limit>
        <dynamics>
          <damping>0</damping>
          <friction>0</friction>
          <spring_reference>0</spring_reference>
          <spring_stiffness>0</spring_stiffness>
        </dynamics>
      </axis>
    </joint>
    <link name='rear_right_leg_link'>
      <pose relative_to='rear_right_leg'>0 0 0 0 -0 0</pose>
      <inertial>
        <pose>0 0 0 0 -0 0</pose>
        <mass>0.15</mass>
        <inertia>
          <ixx>1000</ixx>
          <ixy>0</ixy>
          <ixz>0</ixz>
          <iyy>1000</iyy>
          <iyz>0</iyz>
          <izz>1000</izz>
        </inertia>
      </inertial>
      <collision name='rear_right_leg_link_collision'>
        <pose>0 0 -0.05 0 -0 0</pose>
        <geometry>
          <box>
            <size>0.028 0.036 0.1075</size>
          </box>
        </geometry>
      </collision>
      <visual name='rear_right_leg_link_visual'>
        <pose>0.13 0.15 -0.025 0 -0.139 3.14159</pose>
        <geometry>
          <mesh>
            <scale>0.001 0.001 0.001</scale>
            <uri>model://spot_micro/meshes/rarm.stl</uri>
          </mesh>
        </geometry>
      </visual>
      <visual name='rear_right_leg_link_cover_visual_1'>
        <pose>0.13 0.15 -0.025 0 -0.139 3.14159</pose>
        <geometry>
          <mesh>
            <scale>0.001 0.001 0.001</scale>
            <uri>model://spot_micro/meshes/rarm_cover.stl</uri>
          </mesh>
        </geometry>
      </visual>
    </link>
    <joint name='rear_right_foot' type='revolute'>
      <pose relative_to='rear_right_leg_link'>0 0 -0.1075 0 -0 0</pose>
      <parent>rear_right_leg_link</parent>
      <child>rear_right_foot_link</child>
      <axis>
        <xyz>0 1 0</xyz>
        <limit>
          <lower>-2.6</lower>
          <upper>0.1</upper>
          <effort>1000</effort>
          <velocity>0.5</velocity>
        </limit>
        <dynamics>
          <damping>0</damping>
          <friction>0.5</friction>
          <spring_reference>0</spring_reference>
          <spring_stiffness>0</spring_stiffness>
        </dynamics>
      </axis>
    </joint>
    <link name='rear_right_foot_link'>
      <pose relative_to='rear_right_foot'>0 0 0 0 -0 0</pose>
      <inertial>
        <pose>0 0 -0.043333 0 -0 0</pose>
        <mass>0.15</mass>
        <inertia>
          <ixx>2000</ixx>
          <ixy>0</ixy>
          <ixz>0</ixz>
          <iyy>2000</iyy>
          <iyz>0</iyz>
          <izz>2000</izz>
        </inertia>
      </inertial>
      <collision name='rear_right_foot_link_collision'>
        <pose>0 0 -0.05 0 -0 0</pose>
        <geometry>
          <box>
            <size>0.026 0.02 0.13</size>
          </box>
        </geometry>
      </collision>
      <collision name='rear_right_foot_link_fixed_joint_lump__rear_right_toe_link_collision_1'>
        <pose>0 0 -0.11 0 -0 0</pose>
        <geometry>
          <sphere>
            <radius>0.02</radius>
          </sphere>
        </geometry>
      </collision>
      <visual name='rear_right_foot_link_visual'>
        <pose>0.12 0.15 0.1 0 -0 3.14159</pose>
        <geometry>
          <mesh>
            <scale>0.001 0.001 0.001</scale>
            <uri>model://spot_micro/meshes/rfoot.stl</uri>
          </mesh>
        </geometry>
      </visual>
      <visual name='rear_right_foot_link_fixed_joint_lump__rear_right_toe_link_visual_1'>
        <pose>0 0.01 -0.115 0 -0.4001 3.14159</pose>
        <geometry>
          <mesh>
            <scale>0.001 0.001 0.001</scale>
            <uri>model://spot_micro/meshes/foot.stl</uri>
          </mesh>
        </geometry>
      </visual>
    </link>
    <plugin name='gazebo_ros_joint_state_publisher' filename='libgazebo_ros_joint_state_publisher.so'>
      <ros>
        <namespace>smov</namespace>
      </ros>
      <update_rate>100</update_rate>
      <joint_name>front_left_shoulder</joint_name>
      <joint_name>front_left_leg</joint_name>
      <joint_name>front_left_foot</joint_name>
      <joint_name>front_right_shoulder</joint_name>
      <joint_name>front_right_leg</joint_name>
      <joint_name>front_right_foot</joint_name>
      <joint_name>rear_left_shoulder</joint_name>
      <joint_name>rear_left_leg</joint_name>
      <joint_name>rear_left_foot</joint_name>
      <joint_name>rear_right_shoulder</joint_name>
      <joint_name>rear_right_leg</joint_name>
      <joint_name>rear_right_foot</joint_name>
    </plugin>
    <static>0</static>
  </model>
</sdf>
