<sdf version='1.7'>
  <model name='quadruped'>
    <link name='base_chassis_link'>
      <inertial>
        <pose>0 0 0 0 -0 0</pose>
        <mass>3.2</mass>
        <inertia>
          <ixx>1</ixx>
          <ixy>0</ixy>
          <ixz>0</ixz>
          <iyy>1</iyy>
          <iyz>0</iyz>
          <izz>1</izz>
        </inertia>
      </inertial>
      <collision name='base_chassis_link_collision'>
        <pose>0 0 0 0 -0 0</pose>
        <geometry>
          <box>
            <size>0.226 0.16 0.07</size>
          </box>
        </geometry>
      </collision>
      <visual name='base_chassis_link_visual'>
        <pose>0 0 0 0 -0 0</pose>
        <geometry>
          <box>
            <size>0.226 0.16 0.07</size>
          </box>
        </geometry>
      </visual>
    </link>
    <joint name='motor_back_leftL_joint' type='revolute'>
      <pose relative_to='base_chassis_link'>-0.21 0.06 0 1.57075 -0 0</pose>
      <parent>base_chassis_link</parent>
      <child>motor_back_leftL_link</child>
      <axis>
        <xyz>0 0 1</xyz>
        <limit>
          <effort>100</effort>
          <velocity>100</velocity>
          <lower>-1e+16</lower>
          <upper>1e+16</upper>
        </limit>
        <dynamics>
          <spring_reference>0</spring_reference>
          <spring_stiffness>0</spring_stiffness>
        </dynamics>
      </axis>
    </joint>
    <link name='motor_back_leftL_link'>
      <pose relative_to='motor_back_leftL_joint'>0 0 0 0 -0 0</pose>
      <inertial>
        <pose>0 0.01 -0.003333 0 -0 0</pose>
        <mass>0.3</mass>
        <inertia>
          <ixx>2.00017</ixx>
          <ixy>0</ixy>
          <ixz>0</ixz>
          <iyy>2.00002</iyy>
          <iyz>5e-05</iyz>
          <izz>2.00015</izz>
        </inertia>
      </inertial>
      <collision name='motor_back_leftL_link_collision'>
        <pose>0 0 0 0 -0 0</pose>
        <geometry>
          <cylinder>
            <length>0.026</length>
            <radius>0.0434</radius>
          </cylinder>
        </geometry>
      </collision>
      <collision name='motor_back_leftL_link_fixed_joint_lump__upper_leg_back_leftL_link_collision_1'>
        <pose>0 0.06 -0.02 -1.57075 0 0</pose>
        <geometry>
          <box>
            <size>0.01 0.01 0.11</size>
          </box>
        </geometry>
      </collision>
      <visual name='motor_back_leftL_link_visual'>
        <pose>0 0 0 0 -0 0</pose>
        <geometry>
          <cylinder>
            <length>0.026</length>
            <radius>0.0434</radius>
          </cylinder>
        </geometry>
      </visual>
      <visual name='motor_back_leftL_link_fixed_joint_lump__upper_leg_back_leftL_link_visual_1'>
        <pose>0 0.06 -0.02 -1.57075 0 0</pose>
        <geometry>
          <box>
            <size>0.01 0.01 0.11</size>
          </box>
        </geometry>
      </visual>
    </link>
    <joint name='knee_back_leftL_link' type='revolute'>
      <pose relative_to='motor_back_leftL_link'>0 0.115 -0.019997 -1.57075 0 0</pose>
      <parent>motor_back_leftL_link</parent>
      <child>lower_leg_back_leftL_link</child>
      <axis>
        <xyz>0 1 0</xyz>
        <limit>
          <lower>0</lower>
          <upper>0</upper>
          <effort>100</effort>
          <velocity>100</velocity>
        </limit>
        <dynamics>
          <spring_reference>0</spring_reference>
          <spring_stiffness>0</spring_stiffness>
        </dynamics>
      </axis>
    </joint>
    <link name='lower_leg_back_leftL_link'>
      <pose relative_to='knee_back_leftL_link'>0 0 0 0 -0 0</pose>
      <inertial>
        <pose>0 0 0 0 -0 0</pose>
        <mass>0.05</mass>
        <inertia>
          <ixx>1</ixx>
          <ixy>0</ixy>
          <ixz>0</ixz>
          <iyy>1</iyy>
          <iyz>0</iyz>
          <izz>1</izz>
        </inertia>
      </inertial>
      <collision name='lower_leg_back_leftL_link_collision'>
        <pose>0 0 0.1 0 -0 0</pose>
        <geometry>
          <box>
            <size>0.01 0.01 0.2</size>
          </box>
        </geometry>
      </collision>
      <visual name='lower_leg_back_leftL_link_visual'>
        <pose>0 0 0.1 0 -0 0</pose>
        <geometry>
          <box>
            <size>0.01 0.01 0.2</size>
          </box>
        </geometry>
      </visual>
    </link>
    <joint name='motor_back_leftR_joint' type='revolute'>
      <pose relative_to='base_chassis_link'>-0.21 0.125 0 1.57075 -0 0</pose>
      <parent>base_chassis_link</parent>
      <child>motor_back_leftR_link</child>
      <axis>
        <xyz>0 0 1</xyz>
        <limit>
          <effort>100</effort>
          <velocity>100</velocity>
          <lower>-1e+16</lower>
          <upper>1e+16</upper>
        </limit>
        <dynamics>
          <spring_reference>0</spring_reference>
          <spring_stiffness>0</spring_stiffness>
        </dynamics>
      </axis>
    </joint>
    <link name='motor_back_leftR_link'>
      <pose relative_to='motor_back_leftR_joint'>0 0 0 0 -0 0</pose>
      <inertial>
        <pose>0 0.01 0.003333 0 -0 0</pose>
        <mass>0.3</mass>
        <inertia>
          <ixx>2.00017</ixx>
          <ixy>0</ixy>
          <ixz>0</ixz>
          <iyy>2.00002</iyy>
          <iyz>-5e-05</iyz>
          <izz>2.00015</izz>
        </inertia>
      </inertial>
      <collision name='motor_back_leftR_link_collision'>
        <pose>0 0 0 0 -0 0</pose>
        <geometry>
          <cylinder>
            <length>0.026</length>
            <radius>0.0434</radius>
          </cylinder>
        </geometry>
      </collision>
      <collision name='motor_back_leftR_link_fixed_joint_lump__upper_leg_back_leftR_link_collision_1'>
        <pose>0 0.06 0.02 -1.57075 0 0</pose>
        <geometry>
          <box>
            <size>0.01 0.01 0.11</size>
          </box>
        </geometry>
      </collision>
      <visual name='motor_back_leftR_link_visual'>
        <pose>0 0 0 0 -0 0</pose>
        <geometry>
          <cylinder>
            <length>0.026</length>
            <radius>0.0434</radius>
          </cylinder>
        </geometry>
      </visual>
      <visual name='motor_back_leftR_link_fixed_joint_lump__upper_leg_back_leftR_link_visual_1'>
        <pose>0 0.06 0.02 -1.57075 0 0</pose>
        <geometry>
          <box>
            <size>0.01 0.01 0.11</size>
          </box>
        </geometry>
      </visual>
    </link>
    <joint name='knee_back_leftR_link' type='revolute'>
      <pose relative_to='motor_back_leftR_link'>0 0.115 0.020003 -1.57075 0 0</pose>
      <parent>motor_back_leftR_link</parent>
      <child>lower_leg_back_leftR_link</child>
      <axis>
        <xyz>0 1 0</xyz>
        <limit>
          <lower>0</lower>
          <upper>0</upper>
          <effort>100</effort>
          <velocity>100</velocity>
        </limit>
        <dynamics>
          <spring_reference>0</spring_reference>
          <spring_stiffness>0</spring_stiffness>
        </dynamics>
      </axis>
    </joint>
    <link name='lower_leg_back_leftR_link'>
      <pose relative_to='knee_back_leftR_link'>0 0 0 0 -0 0</pose>
      <inertial>
        <pose>0 0 0 0 -0 0</pose>
        <mass>0.05</mass>
        <inertia>
          <ixx>1</ixx>
          <ixy>0</ixy>
          <ixz>0</ixz>
          <iyy>1</iyy>
          <iyz>0</iyz>
          <izz>1</izz>
        </inertia>
      </inertial>
      <collision name='lower_leg_back_leftR_link_collision'>
        <pose>0 0 0.1 0 -0 0</pose>
        <geometry>
          <box>
            <size>0.01 0.01 0.2</size>
          </box>
        </geometry>
      </collision>
      <visual name='lower_leg_back_leftR_link_visual'>
        <pose>0 0 0.1 0 -0 0</pose>
        <geometry>
          <box>
            <size>0.01 0.01 0.2</size>
          </box>
        </geometry>
      </visual>
    </link>
    <joint name='motor_back_rightL_joint' type='revolute'>
      <pose relative_to='base_chassis_link'>-0.21 -0.06 0 1.57075 -0 0</pose>
      <parent>base_chassis_link</parent>
      <child>motor_back_rightL_link</child>
      <axis>
        <xyz>0 0 1</xyz>
        <limit>
          <effort>100</effort>
          <velocity>100</velocity>
          <lower>-1e+16</lower>
          <upper>1e+16</upper>
        </limit>
        <dynamics>
          <spring_reference>0</spring_reference>
          <spring_stiffness>0</spring_stiffness>
        </dynamics>
      </axis>
    </joint>
    <link name='motor_back_rightL_link'>
      <pose relative_to='motor_back_rightL_joint'>0 0 0 0 -0 0</pose>
      <inertial>
        <pose>0 0.01 0.003333 0 -0 0</pose>
        <mass>0.3</mass>
        <inertia>
          <ixx>2.00017</ixx>
          <ixy>0</ixy>
          <ixz>0</ixz>
          <iyy>2.00002</iyy>
          <iyz>-5e-05</iyz>
          <izz>2.00015</izz>
        </inertia>
      </inertial>
      <collision name='motor_back_rightL_link_collision'>
        <pose>0 0 0 0 -0 0</pose>
        <geometry>
          <cylinder>
            <length>0.026</length>
            <radius>0.0434</radius>
          </cylinder>
        </geometry>
      </collision>
      <collision name='motor_back_rightL_link_fixed_joint_lump__upper_leg_back_rightL_link_collision_1'>
        <pose>0 0.06 0.02 -1.57075 0 0</pose>
        <geometry>
          <box>
            <size>0.01 0.01 0.11</size>
          </box>
        </geometry>
      </collision>
      <visual name='motor_back_rightL_link_visual'>
        <pose>0 0 0 0 -0 0</pose>
        <geometry>
          <cylinder>
            <length>0.026</length>
            <radius>0.0434</radius>
          </cylinder>
        </geometry>
      </visual>
      <visual name='motor_back_rightL_link_fixed_joint_lump__upper_leg_back_rightL_link_visual_1'>
        <pose>0 0.06 0.02 -1.57075 0 0</pose>
        <geometry>
          <box>
            <size>0.01 0.01 0.11</size>
          </box>
        </geometry>
      </visual>
    </link>
    <joint name='knee_back_rightL_link' type='revolute'>
      <pose relative_to='motor_back_rightL_link'>0 0.115 0.020003 -1.57075 0 0</pose>
      <parent>motor_back_rightL_link</parent>
      <child>lower_leg_back_rightL_link</child>
      <axis>
        <xyz>0 1 0</xyz>
        <limit>
          <lower>0</lower>
          <upper>0</upper>
          <effort>100</effort>
          <velocity>100</velocity>
        </limit>
        <dynamics>
          <spring_reference>0</spring_reference>
          <spring_stiffness>0</spring_stiffness>
        </dynamics>
      </axis>
    </joint>
    <link name='lower_leg_back_rightL_link'>
      <pose relative_to='knee_back_rightL_link'>0 0 0 0 -0 0</pose>
      <inertial>
        <pose>0 0 0 0 -0 0</pose>
        <mass>0.05</mass>
        <inertia>
          <ixx>1</ixx>
          <ixy>0</ixy>
          <ixz>0</ixz>
          <iyy>1</iyy>
          <iyz>0</iyz>
          <izz>1</izz>
        </inertia>
      </inertial>
      <collision name='lower_leg_back_rightL_link_collision'>
        <pose>0 0 0.1 0 -0 0</pose>
        <geometry>
          <box>
            <size>0.01 0.01 0.2</size>
          </box>
        </geometry>
      </collision>
      <visual name='lower_leg_back_rightL_link_visual'>
        <pose>0 0 0.1 0 -0 0</pose>
        <geometry>
          <box>
            <size>0.01 0.01 0.2</size>
          </box>
        </geometry>
      </visual>
    </link>
    <joint name='motor_back_rightR_joint' type='revolute'>
      <pose relative_to='base_chassis_link'>-0.21 -0.125 0 1.57075 -0 0</pose>
      <parent>base_chassis_link</parent>
      <child>motor_back_rightR_link</child>
      <axis>
        <xyz>0 0 1</xyz>
        <limit>
          <effort>100</effort>
          <velocity>100</velocity>
          <lower>-1e+16</lower>
          <upper>1e+16</upper>
        </limit>
        <dynamics>
          <spring_reference>0</spring_reference>
          <spring_stiffness>0</spring_stiffness>
        </dynamics>
      </axis>
    </joint>
    <link name='motor_back_rightR_link'>
      <pose relative_to='motor_back_rightR_joint'>0 0 0 0 -0 0</pose>
      <inertial>
        <pose>0 0.01 -0.003333 0 -0 0</pose>
        <mass>0.3</mass>
        <inertia>
          <ixx>2.00017</ixx>
          <ixy>0</ixy>
          <ixz>0</ixz>
          <iyy>2.00002</iyy>
          <iyz>5e-05</iyz>
          <izz>2.00015</izz>
        </inertia>
      </inertial>
      <collision name='motor_back_rightR_link_collision'>
        <pose>0 0 0 0 -0 0</pose>
        <geometry>
          <cylinder>
            <length>0.026</length>
            <radius>0.0434</radius>
          </cylinder>
        </geometry>
      </collision>
      <collision name='motor_back_rightR_link_fixed_joint_lump__upper_leg_back_rightR_link_collision_1'>
        <pose>0 0.06 -0.02 -1.57075 0 0</pose>
        <geometry>
          <box>
            <size>0.01 0.01 0.11</size>
          </box>
        </geometry>
      </collision>
      <visual name='motor_back_rightR_link_visual'>
        <pose>0 0 0 0 -0 0</pose>
        <geometry>
          <cylinder>
            <length>0.026</length>
            <radius>0.0434</radius>
          </cylinder>
        </geometry>
      </visual>
      <visual name='motor_back_rightR_link_fixed_joint_lump__upper_leg_back_rightR_link_visual_1'>
        <pose>0 0.06 -0.02 -1.57075 0 0</pose>
        <geometry>
          <box>
            <size>0.01 0.01 0.11</size>
          </box>
        </geometry>
      </visual>
    </link>
    <joint name='knee_back_rightR_link' type='revolute'>
      <pose relative_to='motor_back_rightR_link'>0 0.115 -0.019997 -1.57075 0 0</pose>
      <parent>motor_back_rightR_link</parent>
      <child>lower_leg_back_rightR_link</child>
      <axis>
        <xyz>0 1 0</xyz>
        <limit>
          <lower>0</lower>
          <upper>0</upper>
          <effort>100</effort>
          <velocity>100</velocity>
        </limit>
        <dynamics>
          <spring_reference>0</spring_reference>
          <spring_stiffness>0</spring_stiffness>
        </dynamics>
      </axis>
    </joint>
    <link name='lower_leg_back_rightR_link'>
      <pose relative_to='knee_back_rightR_link'>0 0 0 0 -0 0</pose>
      <inertial>
        <pose>0 0 0 0 -0 0</pose>
        <mass>0.05</mass>
        <inertia>
          <ixx>1</ixx>
          <ixy>0</ixy>
          <ixz>0</ixz>
          <iyy>1</iyy>
          <iyz>0</iyz>
          <izz>1</izz>
        </inertia>
      </inertial>
      <collision name='lower_leg_back_rightR_link_collision'>
        <pose>0 0 0.1 0 -0 0</pose>
        <geometry>
          <box>
            <size>0.01 0.01 0.2</size>
          </box>
        </geometry>
      </collision>
      <visual name='lower_leg_back_rightR_link_visual'>
        <pose>0 0 0.1 0 -0 0</pose>
        <geometry>
          <box>
            <size>0.01 0.01 0.2</size>
          </box>
        </geometry>
      </visual>
    </link>
    <joint name='motor_front_leftL_joint' type='revolute'>
      <pose relative_to='base_chassis_link'>0.21 0.06 0 1.57075 -0 0</pose>
      <parent>base_chassis_link</parent>
      <child>motor_front_leftL_link</child>
      <axis>
        <xyz>0 0 1</xyz>
        <limit>
          <effort>100</effort>
          <velocity>100</velocity>
          <lower>-1e+16</lower>
          <upper>1e+16</upper>
        </limit>
        <dynamics>
          <spring_reference>0</spring_reference>
          <spring_stiffness>0</spring_stiffness>
        </dynamics>
      </axis>
    </joint>
    <link name='motor_front_leftL_link'>
      <pose relative_to='motor_front_leftL_joint'>0 0 0 0 -0 0</pose>
      <inertial>
        <pose>0 0.01 -0.003333 0 -0 0</pose>
        <mass>0.3</mass>
        <inertia>
          <ixx>2.00017</ixx>
          <ixy>0</ixy>
          <ixz>0</ixz>
          <iyy>2.00002</iyy>
          <iyz>5e-05</iyz>
          <izz>2.00015</izz>
        </inertia>
      </inertial>
      <collision name='motor_front_leftL_link_collision'>
        <pose>0 0 0 0 -0 0</pose>
        <geometry>
          <cylinder>
            <length>0.026</length>
            <radius>0.0434</radius>
          </cylinder>
        </geometry>
      </collision>
      <collision name='motor_front_leftL_link_fixed_joint_lump__upper_leg_front_leftL_link_collision_1'>
        <pose>0 0.06 -0.02 -1.57075 0 0</pose>
        <geometry>
          <box>
            <size>0.01 0.01 0.11</size>
          </box>
        </geometry>
      </collision>
      <visual name='motor_front_leftL_link_visual'>
        <pose>0 0 0 0 -0 0</pose>
        <geometry>
          <cylinder>
            <length>0.026</length>
            <radius>0.0434</radius>
          </cylinder>
        </geometry>
      </visual>
      <visual name='motor_front_leftL_link_fixed_joint_lump__upper_leg_front_leftL_link_visual_1'>
        <pose>0 0.06 -0.02 -1.57075 0 0</pose>
        <geometry>
          <box>
            <size>0.01 0.01 0.11</size>
          </box>
        </geometry>
      </visual>
    </link>
    <joint name='knee_front_leftL_link' type='revolute'>
      <pose relative_to='motor_front_leftL_link'>0 0.115 -0.019997 -1.57075 0 0</pose>
      <parent>motor_front_leftL_link</parent>
      <child>lower_leg_front_leftL_link</child>
      <axis>
        <xyz>0 1 0</xyz>
        <limit>
          <lower>0</lower>
          <upper>0</upper>
          <effort>100</effort>
          <velocity>100</velocity>
        </limit>
        <dynamics>
          <spring_reference>0</spring_reference>
          <spring_stiffness>0</spring_stiffness>
        </dynamics>
      </axis>
    </joint>
    <link name='lower_leg_front_leftL_link'>
      <pose relative_to='knee_front_leftL_link'>0 0 0 0 -0 0</pose>
      <inertial>
        <pose>0 0 0 0 -0 0</pose>
        <mass>0.05</mass>
        <inertia>
          <ixx>1</ixx>
          <ixy>0</ixy>
          <ixz>0</ixz>
          <iyy>1</iyy>
          <iyz>0</iyz>
          <izz>1</izz>
        </inertia>
      </inertial>
      <collision name='lower_leg_front_leftL_link_collision'>
        <pose>0 0 0.1 0 -0 0</pose>
        <geometry>
          <box>
            <size>0.01 0.01 0.2</size>
          </box>
        </geometry>
      </collision>
      <visual name='lower_leg_front_leftL_link_visual'>
        <pose>0 0 0.1 0 -0 0</pose>
        <geometry>
          <box>
            <size>0.01 0.01 0.2</size>
          </box>
        </geometry>
      </visual>
    </link>
    <joint name='motor_front_leftR_joint' type='revolute'>
      <pose relative_to='base_chassis_link'>0.21 0.125 0 1.57075 -0 0</pose>
      <parent>base_chassis_link</parent>
      <child>motor_front_leftR_link</child>
      <axis>
        <xyz>0 0 1</xyz>
        <limit>
          <effort>100</effort>
          <velocity>100</velocity>
          <lower>-1e+16</lower>
          <upper>1e+16</upper>
        </limit>
        <dynamics>
          <spring_reference>0</spring_reference>
          <spring_stiffness>0</spring_stiffness>
        </dynamics>
      </axis>
    </joint>
    <link name='motor_front_leftR_link'>
      <pose relative_to='motor_front_leftR_joint'>0 0 0 0 -0 0</pose>
      <inertial>
        <pose>0 0.01 0.003333 0 -0 0</pose>
        <mass>0.3</mass>
        <inertia>
          <ixx>2.00017</ixx>
          <ixy>0</ixy>
          <ixz>0</ixz>
          <iyy>2.00002</iyy>
          <iyz>-5e-05</iyz>
          <izz>2.00015</izz>
        </inertia>
      </inertial>
      <collision name='motor_front_leftR_link_collision'>
        <pose>0 0 0 0 -0 0</pose>
        <geometry>
          <cylinder>
            <length>0.026</length>
            <radius>0.0434</radius>
          </cylinder>
        </geometry>
      </collision>
      <collision name='motor_front_leftR_link_fixed_joint_lump__upper_leg_front_leftR_link_collision_1'>
        <pose>0 0.06 0.02 -1.57075 0 0</pose>
        <geometry>
          <box>
            <size>0.01 0.01 0.11</size>
          </box>
        </geometry>
      </collision>
      <visual name='motor_front_leftR_link_visual'>
        <pose>0 0 0 0 -0 0</pose>
        <geometry>
          <cylinder>
            <length>0.026</length>
            <radius>0.0434</radius>
          </cylinder>
        </geometry>
      </visual>
      <visual name='motor_front_leftR_link_fixed_joint_lump__upper_leg_front_leftR_link_visual_1'>
        <pose>0 0.06 0.02 -1.57075 0 0</pose>
        <geometry>
          <box>
            <size>0.01 0.01 0.11</size>
          </box>
        </geometry>
      </visual>
    </link>
    <joint name='knee_front_leftR_link' type='revolute'>
      <pose relative_to='motor_front_leftR_link'>0 0.115 0.020003 -1.57075 0 0</pose>
      <parent>motor_front_leftR_link</parent>
      <child>lower_leg_front_leftR_link</child>
      <axis>
        <xyz>0 1 0</xyz>
        <limit>
          <lower>0</lower>
          <upper>0</upper>
          <effort>100</effort>
          <velocity>100</velocity>
        </limit>
        <dynamics>
          <spring_reference>0</spring_reference>
          <spring_stiffness>0</spring_stiffness>
        </dynamics>
      </axis>
    </joint>
    <link name='lower_leg_front_leftR_link'>
      <pose relative_to='knee_front_leftR_link'>0 0 0 0 -0 0</pose>
      <inertial>
        <pose>0 0 0 0 -0 0</pose>
        <mass>0.05</mass>
        <inertia>
          <ixx>1</ixx>
          <ixy>0</ixy>
          <ixz>0</ixz>
          <iyy>1</iyy>
          <iyz>0</iyz>
          <izz>1</izz>
        </inertia>
      </inertial>
      <collision name='lower_leg_front_leftR_link_collision'>
        <pose>0 0 0.1 0 -0 0</pose>
        <geometry>
          <box>
            <size>0.01 0.01 0.2</size>
          </box>
        </geometry>
      </collision>
      <visual name='lower_leg_front_leftR_link_visual'>
        <pose>0 0 0.1 0 -0 0</pose>
        <geometry>
          <box>
            <size>0.01 0.01 0.2</size>
          </box>
        </geometry>
      </visual>
    </link>
    <joint name='motor_front_rightL_joint' type='revolute'>
      <pose relative_to='base_chassis_link'>0.21 -0.06 0 1.57075 -0 0</pose>
      <parent>base_chassis_link</parent>
      <child>motor_front_rightL_link</child>
      <axis>
        <xyz>0 0 1</xyz>
        <limit>
          <effort>100</effort>
          <velocity>100</velocity>
          <lower>-1e+16</lower>
          <upper>1e+16</upper>
        </limit>
        <dynamics>
          <spring_reference>0</spring_reference>
          <spring_stiffness>0</spring_stiffness>
        </dynamics>
      </axis>
    </joint>
    <link name='motor_front_rightL_link'>
      <pose relative_to='motor_front_rightL_joint'>0 0 0 0 -0 0</pose>
      <inertial>
        <pose>0 0.01 0.003333 0 -0 0</pose>
        <mass>0.3</mass>
        <inertia>
          <ixx>2.00017</ixx>
          <ixy>0</ixy>
          <ixz>0</ixz>
          <iyy>2.00002</iyy>
          <iyz>-5e-05</iyz>
          <izz>2.00015</izz>
        </inertia>
      </inertial>
      <collision name='motor_front_rightL_link_collision'>
        <pose>0 0 0 0 -0 0</pose>
        <geometry>
          <cylinder>
            <length>0.026</length>
            <radius>0.0434</radius>
          </cylinder>
        </geometry>
      </collision>
      <collision name='motor_front_rightL_link_fixed_joint_lump__upper_leg_front_rightL_link_collision_1'>
        <pose>0 0.06 0.02 -1.57075 0 0</pose>
        <geometry>
          <box>
            <size>0.01 0.01 0.11</size>
          </box>
        </geometry>
      </collision>
      <visual name='motor_front_rightL_link_visual'>
        <pose>0 0 0 0 -0 0</pose>
        <geometry>
          <cylinder>
            <length>0.026</length>
            <radius>0.0434</radius>
          </cylinder>
        </geometry>
      </visual>
      <visual name='motor_front_rightL_link_fixed_joint_lump__upper_leg_front_rightL_link_visual_1'>
        <pose>0 0.06 0.02 -1.57075 0 0</pose>
        <geometry>
          <box>
            <size>0.01 0.01 0.11</size>
          </box>
        </geometry>
      </visual>
    </link>
    <joint name='knee_front_rightL_link' type='revolute'>
      <pose relative_to='motor_front_rightL_link'>0 0.115 0.020003 -1.57075 0 0</pose>
      <parent>motor_front_rightL_link</parent>
      <child>lower_leg_front_rightL_link</child>
      <axis>
        <xyz>0 1 0</xyz>
        <limit>
          <lower>0</lower>
          <upper>0</upper>
          <effort>100</effort>
          <velocity>100</velocity>
        </limit>
        <dynamics>
          <spring_reference>0</spring_reference>
          <spring_stiffness>0</spring_stiffness>
        </dynamics>
      </axis>
    </joint>
    <link name='lower_leg_front_rightL_link'>
      <pose relative_to='knee_front_rightL_link'>0 0 0 0 -0 0</pose>
      <inertial>
        <pose>0 0 0 0 -0 0</pose>
        <mass>0.05</mass>
        <inertia>
          <ixx>1</ixx>
          <ixy>0</ixy>
          <ixz>0</ixz>
          <iyy>1</iyy>
          <iyz>0</iyz>
          <izz>1</izz>
        </inertia>
      </inertial>
      <collision name='lower_leg_front_rightL_link_collision'>
        <pose>0 0 0.1 0 -0 0</pose>
        <geometry>
          <box>
            <size>0.01 0.01 0.2</size>
          </box>
        </geometry>
      </collision>
      <visual name='lower_leg_front_rightL_link_visual'>
        <pose>0 0 0.1 0 -0 0</pose>
        <geometry>
          <box>
            <size>0.01 0.01 0.2</size>
          </box>
        </geometry>
      </visual>
    </link>
    <joint name='motor_front_rightR_joint' type='revolute'>
      <pose relative_to='base_chassis_link'>0.21 -0.125 0 1.57075 -0 0</pose>
      <parent>base_chassis_link</parent>
      <child>motor_front_rightR_link</child>
      <axis>
        <xyz>0 0 1</xyz>
        <limit>
          <effort>100</effort>
          <velocity>100</velocity>
          <lower>-1e+16</lower>
          <upper>1e+16</upper>
        </limit>
        <dynamics>
          <spring_reference>0</spring_reference>
          <spring_stiffness>0</spring_stiffness>
        </dynamics>
      </axis>
    </joint>
    <link name='motor_front_rightR_link'>
      <pose relative_to='motor_front_rightR_joint'>0 0 0 0 -0 0</pose>
      <inertial>
        <pose>0 0.01 -0.003333 0 -0 0</pose>
        <mass>0.3</mass>
        <inertia>
          <ixx>2.00017</ixx>
          <ixy>0</ixy>
          <ixz>0</ixz>
          <iyy>2.00002</iyy>
          <iyz>5e-05</iyz>
          <izz>2.00015</izz>
        </inertia>
      </inertial>
      <collision name='motor_front_rightR_link_collision'>
        <pose>0 0 0 0 -0 0</pose>
        <geometry>
          <cylinder>
            <length>0.026</length>
            <radius>0.0434</radius>
          </cylinder>
        </geometry>
      </collision>
      <collision name='motor_front_rightR_link_fixed_joint_lump__upper_leg_front_rightR_link_collision_1'>
        <pose>0 0.06 -0.02 -1.57075 0 0</pose>
        <geometry>
          <box>
            <size>0.01 0.01 0.11</size>
          </box>
        </geometry>
      </collision>
      <visual name='motor_front_rightR_link_visual'>
        <pose>0 0 0 0 -0 0</pose>
        <geometry>
          <cylinder>
            <length>0.026</length>
            <radius>0.0434</radius>
          </cylinder>
        </geometry>
      </visual>
      <visual name='motor_front_rightR_link_fixed_joint_lump__upper_leg_front_rightR_link_visual_1'>
        <pose>0 0.06 -0.02 -1.57075 0 0</pose>
        <geometry>
          <box>
            <size>0.01 0.01 0.11</size>
          </box>
        </geometry>
      </visual>
    </link>
    <joint name='knee_front_rightR_link' type='revolute'>
      <pose relative_to='motor_front_rightR_link'>0 0.115 -0.019997 -1.57075 0 0</pose>
      <parent>motor_front_rightR_link</parent>
      <child>lower_leg_front_rightR_link</child>
      <axis>
        <xyz>0 1 0</xyz>
        <limit>
          <lower>0</lower>
          <upper>0</upper>
          <effort>100</effort>
          <velocity>100</velocity>
        </limit>
        <dynamics>
          <spring_reference>0</spring_reference>
          <spring_stiffness>0</spring_stiffness>
        </dynamics>
      </axis>
    </joint>
    <link name='lower_leg_front_rightR_link'>
      <pose relative_to='knee_front_rightR_link'>0 0 0 0 -0 0</pose>
      <inertial>
        <pose>0 0 0 0 -0 0</pose>
        <mass>0.05</mass>
        <inertia>
          <ixx>1</ixx>
          <ixy>0</ixy>
          <ixz>0</ixz>
          <iyy>1</iyy>
          <iyz>0</iyz>
          <izz>1</izz>
        </inertia>
      </inertial>
      <collision name='lower_leg_front_rightR_link_collision'>
        <pose>0 0 0.1 0 -0 0</pose>
        <geometry>
          <box>
            <size>0.01 0.01 0.2</size>
          </box>
        </geometry>
      </collision>
      <visual name='lower_leg_front_rightR_link_visual'>
        <pose>0 0 0.1 0 -0 0</pose>
        <geometry>
          <box>
            <size>0.01 0.01 0.2</size>
          </box>
        </geometry>
      </visual>
    </link>
  </model>
</sdf>
